06:04:44.489 [I] Loaded norm stats from /home/alex/pi0_hack/assets/pi0_libero/your_hf_username/libero (1690920:config.py:179)
Returning existing local_dir `/home/alex/.cache/huggingface/lerobot/your_hf_username/libero` as remote repo cannot be accessed in `snapshot_download` (None).
06:04:44.490 [W] Returning existing local_dir `/home/alex/.cache/huggingface/lerobot/your_hf_username/libero` as remote repo cannot be accessed in `snapshot_download` (None). (1690920:_snapshot_download.py:213)
Traceback (most recent call last):
  File "<frozen runpy>", line 198, in _run_module_as_main
  File "<frozen runpy>", line 88, in _run_code
  File "/home/alex/pi0_hack/scripts/train.py", line 273, in <module>
    main(_config.cli())
  File "/home/alex/pi0_hack/scripts/train.py", line 219, in main
    data_loader = _data_loader.create_data_loader(
                  ^^^^^^^^^^^^^^^^^^^^^^^^^^^^^^^^
  File "/home/alex/pi0_hack/src/openpi/training/data_loader.py", line 171, in create_data_loader
    dataset = create_dataset(data_config, config.model)
              ^^^^^^^^^^^^^^^^^^^^^^^^^^^^^^^^^^^^^^^^^
  File "/home/alex/pi0_hack/src/openpi/training/data_loader.py", line 100, in create_dataset
    dataset_meta = lerobot_dataset.LeRobotDatasetMetadata(
                   ^^^^^^^^^^^^^^^^^^^^^^^^^^^^^^^^^^^^^^^
  File "/home/alex/pi0_hack/.venv/lib/python3.11/site-packages/lerobot/common/datasets/lerobot_dataset.py", line 88, in __init__
    self.info = load_info(self.root)
                ^^^^^^^^^^^^^^^^^^^^
  File "/home/alex/pi0_hack/.venv/lib/python3.11/site-packages/lerobot/common/datasets/utils.py", line 157, in load_info
    info = load_json(local_dir / INFO_PATH)
           ^^^^^^^^^^^^^^^^^^^^^^^^^^^^^^^^
  File "/home/alex/pi0_hack/.venv/lib/python3.11/site-packages/lerobot/common/datasets/utils.py", line 129, in load_json
    with open(fpath) as f:
         ^^^^^^^^^^^
FileNotFoundError: [Errno 2] No such file or directory: '/home/alex/.cache/huggingface/lerobot/your_hf_username/libero/meta/info.json'
